Workbook

Sheet README
A1: Digital Skills Centre — Data Analytics Programme
A2: Week 2 — Sales Dataset
A4: One row per order. 2025 full year. This dataset is used for all four days of Week 2.
A6: Sheets
A7: Sales — the order data. Convert it to a Table and name it Sales.
A8: Targets — the monthly revenue target for each region. You will need this for IF.
A9: Answers — build your formulas here, not on the data sheet.
A11: Fields
A12: order_id · order_date · region · sales_rep · channel · product · category
A13: quantity · unit_price_ngn · unit_cost_ngn · discount_pct · delivery_days
A15: Two things to work out for yourself before you start
A16: 1. There is no revenue column. Revenue = quantity × unit_price × (1 − discount_pct).
... A25: You will join it to the customer master on Wednesday.

Sheet Customers
A1: customer_id | B1: first_name | C1: last_name | D1: customer_name | E1: email | F1: phone | G1: city | H1: state | I1: signup_date | J1: segment | K1: credit_limit_ngn | L1: customers_orders
A2: CUS-2105 | B2: Adaeze | C2: Nnamdi | D2: Adaeze Nnamdi | E2: adaeze.nnamdi@example.com | G2: Ibadan | H2: Oyo | I2: 2025-04-27 | J2: Retail | K2: 150000 | L2: =COUNTIF(Sales[customer_id],Cust[[#This Row],[customer_id]]) -> 0
A3: CUS-2028 | B3: Chidi | C3: Nwosu | D3: Chidi Nwosu | E3: chidi.nwosu@example.com | F3: 08093639437 | G3: Ibadan | H3: Oyo | I3: 2025-08-25 | J3: Retail | K3: 500000 | L3: =COUNTIF(Sales[customer_id],Cust[[#This Row],[customer_id]]) -> 2
A4: CUS-2060 | B4: Jide | C4: Umeh | D4: Jide Umeh | E4: jide.umeh@example.com | F4: 08026428932 | G4: Lagos | H4: Lagos | I4: 2024-06-21 | J4: Wholesale | K4: 100000 | L4: =COUNTIF(Sales[customer_id],Cust[[#This Row],[customer_id]]) -> 3
A5: CUS-2003 | B5: Tunde | C5: Mohammed | D5: Tunde Mohammed | E5: tunde.mohammed@example.com | F5: 08035666553 | G5: Ibadan | H5: Oyo | I5: 2024-06-25 | J5: Retail | K5: 250000 | L5: =COUNTIF(Sales[customer_id],Cust[[#This Row],[customer_id]]) -> 3
A6: CUS-2086 | B6: Emeka | C6: Balogun | D6: Emeka Balogun | E6: emeka.balogun@example.com | F6: 08092899702 | G6: Lagos | H6: Lagos | I6: 2025-06-25 | J6: Wholesale | K6: 150000 | L6: =COUNTIF(Sales[customer_id],Cust[[#This Row],[customer_id]]) -> 5
A7: CUS-2059 | B7: Adaeze | C7: Balogun | D7: Adaeze Balogun | E7: adaeze.balogun@example.com | F7: 08070190705 | G7: Lagos | H7: Lagos | I7: 2025-05-06 | J7: Wholesale | K7: 250000 | L7: =COUNTIF(Sales[customer_id],Cust[[#This Row],[customer_id]]) -> 5
A8: CUS-2101 | B8: Hauwa | C8: Okafor | D8: Hauwa Okafor | E8: hauwa.okafor@example.com | F8: 08089549610 | G8: Kano | H8: Kano | I8: 2025-05-29 | J8: Wholesale | K8: 100000 | L8: =COUNTIF(Sales[customer_id],Cust[[#This Row],[customer_id]]) -> 2
A9: CUS-2045 | B9: Blessing | C9: Eze | D9: Blessing Eze | E9: blessing.eze@example.com | F9: 08057745602 | G9: Abuja | H9: FCT | I9: 2025-07-08 | J9: Retail | K9: 250000 | L9: =COUNTIF(Sales[customer_id],Cust[[#This Row],[customer_id]]) -> 2
A10: CUS-2052 | B10: Ifeoma | C10: Adebayo | D10: Ifeoma Adebayo | E10: ifeoma.adebayo@example.com | F10: 08073508072 | G10: Abuja | H10: FCT | I10: 2024-01-25 | J10: Retail | K10: 500000 | L10: =COUNTIF(Sales[customer_id],Cust[[#This Row],[customer_id]]) -> 4
A11: CUS-2116 | B11: Sadiq | C11: Chukwu | D11: Sadiq Chukwu | F11: 08023757759 | G11: Abuja | H11: FCT | I11: 2024-07-01 | J11: Wholesale | K11: 500000 | L11: =COUNTIF(Sales[customer_id],Cust[[#This Row],[customer_id]]) -> 8
A12: CUS-2079 | B12: Chinelo | C12: Jibril | D12: Chinelo Jibril | E12: chinelo.jibril@example.com | F12: 08061052474 | G12: Port Harcourt | H12: Rivers | I12: 2025-02-12 | J12: Wholesale | K12: 50000 | L12: =COUNTIF(Sales[customer_id],Cust[[#This Row],[customer_id]]) -> 2
A13: CUS-2030 | B13: Obinna | C13: Kalu | D13: Obinna Kalu | E13: obinna.kalu@example.com | G13: Lagos | H13: Lagos | I13: 2024-12-17 | J13: Wholesale | K13: 500000 | L13: =COUNTIF(Sales[customer_id],Cust[[#This Row],[customer_id]]) -> 3
A14: CUS-2065 | B14: Uche | C14: Sanni | D14: Uche Sanni | E14: uche.sanni@example.com | F14: 08034248880 | G14: Port Harcourt | H14: Rivers | I14: 2025-05-23 | J14: Corporate | K14: 250000 | L14: =COUNTIF(Sales[customer_id],Cust[[#This Row],[customer_id]]) -> 4
A15: CUS-2085 | B15: Tunde | C15: Ogunleye | D15: Tunde Ogunleye | E15: tunde.ogunleye@example.com | F15: 08064244757 | G15: Kano | H15: Kano | I15: 2025-02-20 | J15: Retail | K15: 50000 | L15: =COUNTIF(Sales[customer_id],Cust[[#This Row],[customer_id]]) -> 5
A16: CUS-2111 | B16: Blessing | C16: Obi | D16: Blessing Obi | E16: blessing.obi@example.com | F16: 08065119254 | G16: Lagos | H16: Lagos | I16: 2025-04-20 | J16: Retail | K16: 250000 | L16: =COUNTIF(Sales[customer_id],Cust[[#This Row],[customer_id]]) -> 3
A17: CUS-2093 | B17: Nneka | C17: Oyelaran | D17: Nneka Oyelaran | E17: nneka.oyelaran@example.com | F17: 08015694677 | G17: Kano | H17: Kano | J17: Corporate | K17: 500000 | L17: =COUNTIF(Sales[customer_id],Cust[[#This Row],[customer_id]]) -> 3
A18: CUS-2112 | B18: Dayo | C18: Musa | D18: Dayo Musa | E18: dayo.musa@example.com | F18: 08069067214 | G18: Ibadan | H18: Oyo | I18: 2024-11-01 | J18: Retail | K18: 150000 | L18: =COUNTIF(Sales[customer_id],Cust[[#This Row],[customer_id]]) -> 4
A19: CUS-2055 | B19: Bashir | C19: Umeh | D19: Bashir Umeh | E19: bashir.umeh@example.com | F19: 08020318347 | G19: Lagos | H19: Lagos | I19: 2025-07-04 | J19: Corporate | K19: 500000 | L19: =COUNTIF(Sales[customer_id],Cust[[#This Row],[customer_id]]) -> 0
A20: CUS-2115 | B20: Damilola | C20: Nwosu | D20: Damilola Nwosu | E20: damilola.nwosu@example.com | F20: 08050022699 | G20: Lagos | H20: Lagos | I20: 2025-09-09 | J20: Retail | K20: 50000 | L20: =COUNTIF(Sales[customer_id],Cust[[#This Row],[customer_id]]) -> 1
A21: CUS-2088 | B21: Fatima | C21: Peters | D21: Fatima Peters | E21: fatima.peters@example.com | F21: 08052529204 | G21: Lagos | H21: Lagos | I21: 2025-03-15 | J21: Wholesale | K21: 150000 | L21: =COUNTIF(Sales[customer_id],Cust[[#This Row],[customer_id]]) -> 4
A22: CUS-2069 | B22: Femi | C22: Nwachukwu | D22: Femi Nwachukwu | E22: femi.nwachukwu@example.con | F22: 08085088022 | G22: Lagos | H22: Lagos | I22: 2024-06-15 | J22: Corporate | K22: 150000 | L22: =COUNTIF(Sales[customer_id],Cust[[#This Row],[customer_id]]) -> 2
A23: CUS-2031 | B23: Jide | C23: Lawal | D23: Jide Lawal | E23: jide.lawal@example.com | F23: 08020577895 | G23: Lagos | H23: Lagos | I23: 2024-11-03 | J23: Retail | K23: 500000 | L23: =COUNTIF(Sales[customer_id],Cust[[#This Row],[customer_id]]) -> 1
A24: CUS-2080 | B24: Musa | C24: Nwosu | D24: Musa Nwosu | E24: musa.nwosu@example.com | F24: 08062699461 | G24: Lagos | H24: Lagos | I24: 2024-07-30 | J24: Corporate | K24: 50000 | L24: =COUNTIF(Sales[customer_id],Cust[[#This Row],[customer_id]]) -> 0
A25: CUS-2012 | B25: Emeka | C25: Ibrahim | D25: Emeka Ibrahim | E25: emeka.ibrahim@example.com | F25: 08075615636 | G25: Ibadan | H25: Oyo | I25: 2025-07-30 | J25: Retail | K25: 250000 | L25: =COUNTIF(Sales[customer_id],Cust[[#This Row],[customer_id]]) -> 2
A26: CUS-2074 | B26: Aisha | C26: Okafor | D26: Aisha Okafor | E26: aisha.okafor@example.com | F26: 08055595154 | G26: Ibadan | H26: Oyo | I26: 2024-04-19 | J26: Corporate | K26: 100000 | L26: =COUNTIF(Sales[customer_id],Cust[[#This Row],[customer_id]]) -> 4
A27: CUS-2113 | B27: Blessing | C27: Nnamdi | D27: Blessing Nnamdi | E27: blessing.nnamdi@example.com | F27: 08030323591 | G27: Ibadan | H27: Oyo | I27: 2025-07-14 | J27: Retail | K27: 100000 | L27: =COUNTIF(Sales[customer_id],Cust[[#This Row],[customer_id]]) -> 3
A28: CUS-2051 | B28: Uche | C28: Chukwu | D28: Uche Chukwu | E28: uche.chukwu@example.com | F28: 08044350672 | G28: Ibadan | H28: Oyo | I28: 2025-11-10 | J28: Wholesale | K28: 100000 | L28: =COUNTIF(Sales[customer_id],Cust[[#This Row],[customer_id]]) -> 4
A29: CUS-2033 | B29: Fatima | C29: Ogunleye | D29: Fatima Ogunleye | E29: fatima.ogunleye@example.com | F29: 08060449127 | G29: Lagos | H29: Lagos | I29: 2024-02-02 | J29: Wholesale | K29: 50000 | L29: =COUNTIF(Sales[customer_id],Cust[[#This Row],[customer_id]]) -> 1
... A35: CUS-2006 | B35: Maryam | C35: Oyelaran | D35: Maryam Oyelaran | E35: maryam.oyelaran@example.com | F35: 08023400909 | G35: Port Harcourt | H35: Rivers | I35: 2024-03-19 | J35: Corporate | K35: 100000 | L35: =COUNTIF(Sales[customer_id],Cust[[#This Row],[customer_id]]) -> 5
A36: CUS-2063 | B36: Dayo | C36: Jibril | D36: Dayo Jibril | F36: 08066789777 | G36: Ibadan | H36: Oyo | I36: 2024-01-26 | J36: Corporate | K36: 100000 | L36: =COUNTIF(Sales[customer_id],Cust[[#This Row],[customer_id]]) -> 2
A37: CUS-2016 | B37: Blessing | C37: Ojo | D37: Blessing Ojo | F37: 08045101662 | G37: Kano | H37: Kano | I37: 2024-09-02 | J37: Retail | K37: 50000 | L37: =COUNTIF(Sales[customer_id],Cust[[#This Row],[customer_id]]) -> 4
A38: CUS-2090 | B38: Tunde | C38: Sanni | D38: Tunde Sanni | E38: tunde.sanni@example.com | F38: 08056055382 | G38: Abuja | H38: FCT | I38: 2024-05-04 | J38: Corporate | K38: 50000 | L38: =COUNTIF(Sales[customer_id],Cust[[#This Row],[customer_id]]) -> 6
A39: CUS-2081 | B39: Blessing | C39: Adeleke | D39: Blessing Adeleke | E39: blessing.adeleke@example.com | F39: 08058059832 | G39: Lagos | H39: Lagos | I39: 2025-08-23 | J39: Wholesale | K39: 500000 | L39: =COUNTIF(Sales[customer_id],Cust[[#This Row],[customer_id]]) -> 1
A40: CUS-2013 | B40: Blessing | C40: Yusuf | D40: Blessing Yusuf | E40: blessing.yusuf@example.com | F40: 08012304485 | G40: Lagos | H40: Lagos | I40: 2024-04-04 | J40: Corporate | K40: 150000 | L40: =COUNTIF(Sales[customer_id],Cust[[#This Row],[customer_id]]) -> 4
A41: CUS-2035 | B41: Gbenga | C41: Ojo | D41: Gbenga Ojo | E41: gbenga.ojo@example.com | F41: 08016048683 | G41: Port Harcourt | H41: Rivers | I41: 2024-03-12 | J41: Retail | K41: 250000 | L41: =COUNTIF(Sales[customer_id],Cust[[#This Row],[customer_id]]) -> 6
A42: CUS-2017 | B42: Yemi | C42: Adeyemi | D42: Yemi Adeyemi | E42: yemi.adeyemi@example.com | F42: 08041319377 | G42: Lagos | H42: Lagos | I42: 2024-02-21 | J42: Wholesale | K42: 250000 | L42: =COUNTIF(Sales[customer_id],Cust[[#This Row],[customer_id]]) -> 1
A43: CUS-2025 | B43: Obinna | C43: Chukwu | D43: Obinna Chukwu | E43: obinna.chukwu@example.com | F43: 08074165816 | G43: Kano | H43: Kano | I43: 2025-11-28 | J43: Corporate | K43: 500000 | L43: =COUNTIF(Sales[customer_id],Cust[[#This Row],[customer_id]]) -> 1
A44: CUS-2066 | B44: Grace | C44: Yusuf | D44: Grace Yusuf | E44: grace.yusuf@example.com | F44: 08016695186 | G44: Lagos | H44: Lagos | I44: 2024-02-06 | J44: Retail | K44: 150000 | L44: =COUNTIF(Sales[customer_id],Cust[[#This Row],[customer_id]]) -> 3
A45: CUS-2103 | B45: Emeka | C45: Danjuma | D45: Emeka Danjuma | E45: emeka.danjuma@example.com | F45: 08056740511 | G45: Lagos | H45: Lagos | I45: 2024-01-18 | J45: Retail | K45: 100000 | L45: =COUNTIF(Sales[customer_id],Cust[[#This Row],[customer_id]]) -> 5
...

Sheet Sales
A1: order_id | B1: order_date | C1: region | D1: sales_rep | E1: channel | F1: product | G1: category | H1: quantity | I1: unit_price_ngn | J1: unit_cost_ngn | K1: discount_pct | L1: delivery_days | M1: customer_id | N1: credit_limit_ngn | O1: city | P1: customer_name | Q1: segment | R1: revenue | S1: Profit_ngn | T1: Month
A2: ORD-7122 | B2: 45660 | C2: Abuja | D2: Ngozi Eze | E2: Web | F2: Palm Oil 5L | G2: Groceries | H2: 1 | I2: 9800 | J2: 7600 | K2: 0.1 | L2: 7 | M2: CUS-2102 | N2: =_xlfn.IFNA(VLOOKUP(Sales[customer_id],Cust[],11,FALSE),"Unknown") -> 250000 | O2: =_xlfn.IFNA(VLOOKUP(Sales[customer_id], Cust[], 7,FALSE),"Unknown customer") -> Abuja | P2: =_xlfn.IFNA(VLOOKUP(Sales[customer_id],Cust[],4, FALSE),"Unknown customer") -> Bola Musa | Q2: =_xlfn.IFNA(VLOOKUP(Sales[customer_id], Cust[], 10, FALSE), "Unknown customer") -> Corporate | R2: =SUM(Sales[quantity]*Sales[[#This Row],[unit_price_ngn]]*(1-Sales[[#This Row],[discount_pct]])) -> 8820 | S2: =Sales[[#This Row],[revenue]]-(Sales[[#This Row],[quantity]]*Sales[[#This Row],[unit_cost_ngn]]) -> 1220 | T2: =TEXT(Sales[order_date], "yyyy-mm") -> 2025-01
A3: ORD-7166 | B3: 45660 | C3: Abuja | D3: Ngozi Eze | E3: Walk-in | F3: Ankle Boots | G3: Fashion | H3: 3 | I3: 41000 | J3: 25000 | K3: 0 | L3: 5 | M3: CUS-2032 | N3: =_xlfn.IFNA(VLOOKUP(Sales[customer_id],Cust[],11,FALSE),"Unknown") -> 500000 | O3: =_xlfn.IFNA(VLOOKUP(Sales[customer_id], Cust[], 7,FALSE),"Unknown customer") -> Abuja | P3: =_xlfn.IFNA(VLOOKUP(Sales[[#This Row],[customer_id]],Cust[],4, FALSE),"Unknown customer") -> Amaka Bello | Q3: =_xlfn.IFNA(VLOOKUP(Sales[[#This Row],[customer_id]], Cust[], 10, FALSE), "Unknown customer") -> Retail | R3: =SUM(Sales[quantity]*Sales[[#This Row],[unit_price_ngn]]*(1-Sales[[#This Row],[discount_pct]])) -> 123000 | S3: =Sales[[#This Row],[revenue]]-(Sales[[#This Row],[quantity]]*Sales[[#This Row],[unit_cost_ngn]]) -> 48000 | T3: =TEXT(Sales[order_date], "yyyy-mm") -> 2025-01
A4: ORD-7121 | B4: 45661 | C4: Abuja | D4: Ngozi Eze | E4: Web | F4: Ankara Fabric 6yd | G4: Textiles | H4: 1 | I4: 12000 | J4: 7200 | K4: 0 | L4: 5 | M4: CUS-2102 | N4: =_xlfn.IFNA(VLOOKUP(Sales[customer_id],Cust[],11,FALSE),"Unknown") -> 250000 | O4: =_xlfn.IFNA(VLOOKUP(Sales[customer_id], Cust[], 7,FALSE),"Unknown customer") -> Abuja | P4: =_xlfn.IFNA(VLOOKUP(Sales[[#This Row],[customer_id]],Cust[],4, FALSE),"Unknown customer") -> Bola Musa | Q4: =_xlfn.IFNA(VLOOKUP(Sales[[#This Row],[customer_id]], Cust[], 10, FALSE), "Unknown customer") -> Corporate | R4: =SUM(Sales[quantity]*Sales[[#This Row],[unit_price_ngn]]*(1-Sales[[#This Row],[discount_pct]])) -> 12000 | S4: =Sales[[#This Row],[revenue]]-(Sales[[#This Row],[quantity]]*Sales[[#This Row],[unit_cost_ngn]]) -> 4800 | T4: =TEXT(Sales[order_date], "yyyy-mm") -> 2025-01
A5: ORD-7248 | B5: 45662 | C5: Abuja | D5: Ngozi Eze | E5: Walk-in | F5: Blender 1.5L | G5: Home | H5: 1 | I5: 32000 | J5: 21000 | K5: 0 | L5: 2 | M5: CUS-2044 | N5: =_xlfn.IFNA(VLOOKUP(Sales[customer_id],Cust[],11,FALSE),"Unknown") -> 250000 | O5: =_xlfn.IFNA(VLOOKUP(Sales[customer_id], Cust[], 7,FALSE),"Unknown customer") -> Abuja | P5: =_xlfn.IFNA(VLOOKUP(Sales[[#This Row],[customer_id]],Cust[],4, FALSE),"Unknown customer") -> Funmi Musa | Q5: =_xlfn.IFNA(VLOOKUP(Sales[[#This Row],[customer_id]], Cust[], 10, FALSE), "Unknown customer") -> Wholesale | R5: =SUM(Sales[quantity]*Sales[[#This Row],[unit_price_ngn]]*(1-Sales[[#This Row],[discount_pct]])) -> 32000 | S5: =Sales[[#This Row],[revenue]]-(Sales[[#This Row],[quantity]]*Sales[[#This Row],[unit_cost_ngn]]) -> 11000 | T5: =TEXT(Sales[order_date], "yyyy-mm") -> 2025-01
A6: ORD-7115 | B6: 45664 | C6: Abuja | D6: Ngozi Eze | E6: Mobile App | F6: Sneakers | G6: Fashion | H6: 1 | I6: 27500 | J6: 16500 | K6: 0.05 | L6: 3 | M6: CUS-2026 | N6: =_xlfn.IFNA(VLOOKUP(Sales[customer_id],Cust[],11,FALSE),"Unknown") -> 500000 | O6: =_xlfn.IFNA(VLOOKUP(Sales[customer_id], Cust[], 7,FALSE),"Unknown customer") -> Abuja | P6: =_xlfn.IFNA(VLOOKUP(Sales[[#This Row],[customer_id]],Cust[],4, FALSE),"Unknown customer") -> Temitope Nnamdi | Q6: =_xlfn.IFNA(VLOOKUP(Sales[[#This Row],[customer_id]], Cust[], 10, FALSE), "Unknown customer") -> Corporate | R6: =SUM(Sales[quantity]*Sales[[#This Row],[unit_price_ngn]]*(1-Sales[[#This Row],[discount_pct]])) -> 26125 | S6: =Sales[[#This Row],[revenue]]-(Sales[[#This Row],[quantity]]*Sales[[#This Row],[unit_cost_ngn]]) -> 9625 | T6: =TEXT(Sales[order_date], "yyyy-mm") -> 2025-01
A7: ORD-7164 | B7: 45673 | C7: Abuja | D7: Ngozi Eze | E7: Web | F7: Bedsheet Set | G7: Home | H7: 1 | I7: 24000 | J7: 14500 | K7: 0 | L7: 7 | M7: CUS-2109 | N7: =_xlfn.IFNA(VLOOKUP(Sales[customer_id],Cust[],11,FALSE),"Unknown") -> 50000 | O7: =_xlfn.IFNA(VLOOKUP(Sales[customer_id], Cust[], 7,FALSE),"Unknown customer") -> Abuja | P7: =_xlfn.IFNA(VLOOKUP(Sales[[#This Row],[customer_id]],Cust[],4, FALSE),"Unknown customer") -> Halima Ibrahim | Q7: =_xlfn.IFNA(VLOOKUP(Sales[[#This Row],[customer_id]], Cust[], 10, FALSE), "Unknown customer") -> Retail | R7: =SUM(Sales[quantity]*Sales[[#This Row],[unit_price_ngn]]*(1-Sales[[#This Row],[discount_pct]])) -> 24000 | S7: =Sales[[#This Row],[revenue]]-(Sales[[#This Row],[quantity]]*Sales[[#This Row],[unit_cost_ngn]]) -> 9500 | T7: =TEXT(Sales[order_date], "yyyy-mm") -> 2025-01
A8: ORD-7398 | B8: 45676 | C8: Abuja | D8: Ngozi Eze | E8: Phone | F8: Blender 1.5L | G8: Home | H8: 1 | I8: 32000 | J8: 21000 | K8: 0 | L8: 2 | M8: CUS-2116 | N8: =_xlfn.IFNA(VLOOKUP(Sales[customer_id],Cust[],11,FALSE),"Unknown") -> 500000 | O8: =_xlfn.IFNA(VLOOKUP(Sales[customer_id], Cust[], 7,FALSE),"Unknown customer") -> Abuja | P8: =_xlfn.IFNA(VLOOKUP(Sales[[#This Row],[customer_id]],Cust[],4, FALSE),"Unknown customer") -> Sadiq Chukwu | Q8: =_xlfn.IFNA(VLOOKUP(Sales[[#This Row],[customer_id]], Cust[], 10, FALSE), "Unknown customer") -> Wholesale | R8: =SUM(Sales[quantity]*Sales[[#This Row],[unit_price_ngn]]*(1-Sales[[#This Row],[discount_pct]])) -> 32000 | S8: =Sales[[#This Row],[revenue]]-(Sales[[#This Row],[quantity]]*Sales[[#This Row],[unit_cost_ngn]]) -> 11000 | T8: =TEXT(Sales[order_date], "yyyy-mm") -> 2025-01
A9: ORD-7215 | B9: 45678 | C9: Abuja | D9: Ngozi Eze | E9: Walk-in | F9: Ankara Fabric 6yd | G9: Textiles | H9: 3 | I9: 12000 | J9: 7200 | K9: 0 | L9: 1 | M9: CUS-2102 | N9: =_xlfn.IFNA(VLOOKUP(Sales[customer_id],Cust[],11,FALSE),"Unknown") -> 250000 | O9: =_xlfn.IFNA(VLOOKUP(Sales[customer_id], Cust[], 7,FALSE),"Unknown customer") -> Abuja | P9: =_xlfn.IFNA(VLOOKUP(Sales[[#This Row],[customer_id]],Cust[],4, FALSE),"Unknown customer") -> Bola Musa | Q9: =_xlfn.IFNA(VLOOKUP(Sales[[#This Row],[customer_id]], Cust[], 10, FALSE), "Unknown customer") -> Corporate | R9: =SUM(Sales[quantity]*Sales[[#This Row],[unit_price_ngn]]*(1-Sales[[#This Row],[discount_pct]])) -> 36000 | S9: =Sales[[#This Row],[revenue]]-(Sales[[#This Row],[quantity]]*Sales[[#This Row],[unit_cost_ngn]]) -> 14400 | T9: =TEXT(Sales[order_date], "yyyy-mm") -> 2025-01
A10: ORD-7345 | B10: 45682 | C10: Abuja | D10: Ngozi Eze | E10: Phone | F10: Palm Oil 5L | G10: Groceries | H10: 1 | I10: 9800 | J10: 7600 | K10: 0 | L10: 1 | M10: CUS-2116 | N10: =_xlfn.IFNA(VLOOKUP(Sales[customer_id],Cust[],11,FALSE),"Unknown") -> 500000 | O10: =_xlfn.IFNA(VLOOKUP(Sales[customer_id], Cust[], 7,FALSE),"Unknown customer") -> Abuja | P10: =_xlfn.IFNA(VLOOKUP(Sales[[#This Row],[customer_id]],Cust[],4, FALSE),"Unknown customer") -> Sadiq Chukwu | Q10: =_xlfn.IFNA(VLOOKUP(Sales[[#This Row],[customer_id]], Cust[], 10, FALSE), "Unknown customer") -> Wholesale | R10: =SUM(Sales[quantity]*Sales[[#This Row],[unit_price_ngn]]*(1-Sales[[#This Row],[discount_pct]])) -> 9800 | S10: =Sales[[#This Row],[revenue]]-(Sales[[#This Row],[quantity]]*Sales[[#This Row],[unit_cost_ngn]]) -> 2200 | T10: =TEXT(Sales[order_date], "yyyy-mm") -> 2025-01
A11: ORD-7410 | B11: 45699 | C11: Abuja | D11: Ngozi Eze | E11: Phone | F11: Body Lotion 400ml | G11: Beauty | H11: 10 | I11: 6800 | J11: 3900 | K11: 0 | L11: 1 | M11: CUS-2114 | N11: =_xlfn.IFNA(VLOOKUP(Sales[customer_id],Cust[],11,FALSE),"Unknown") -> 100000 | O11: =_xlfn.IFNA(VLOOKUP(Sales[customer_id], Cust[], 7,FALSE),"Unknown customer") -> Abuja | P11: =_xlfn.IFNA(VLOOKUP(Sales[[#This Row],[customer_id]],Cust[],4, FALSE),"Unknown customer") -> Hauwa Sanni | Q11: =_xlfn.IFNA(VLOOKUP(Sales[[#This Row],[customer_id]], Cust[], 10, FALSE), "Unknown customer") -> Retail | R11: =SUM(Sales[quantity]*Sales[[#This Row],[unit_price_ngn]]*(1-Sales[[#This Row],[discount_pct]])) -> 68000 | S11: =Sales[[#This Row],[revenue]]-(Sales[[#This Row],[quantity]]*Sales[[#This Row],[unit_cost_ngn]]) -> 29000 | T11: =TEXT(Sales[order_date], "yyyy-mm") -> 2025-02
A12: ORD-7048 | B12: 45705 | C12: Abuja | D12: Ngozi Eze | E12: Phone | F12: Blender 1.5L | G12: Home | H12: 2 | I12: 32000 | J12: 21000 | K12: 0 | L12: 4 | M12: CUS-2070 | N12: =_xlfn.IFNA(VLOOKUP(Sales[customer_id],Cust[],11,FALSE),"Unknown") -> 150000 | O12: =_xlfn.IFNA(VLOOKUP(Sales[customer_id], Cust[], 7,FALSE),"Unknown customer") -> Abuja | P12: =_xlfn.IFNA(VLOOKUP(Sales[[#This Row],[customer_id]],Cust[],4, FALSE),"Unknown customer") -> Emeka Fashola | Q12: =_xlfn.IFNA(VLOOKUP(Sales[[#This Row],[customer_id]], Cust[], 10, FALSE), "Unknown customer") -> Retail | R12: =SUM(Sales[quantity]*Sales[[#This Row],[unit_price_ngn]]*(1-Sales[[#This Row],[discount_pct]])) -> 64000 | S12: =Sales[[#This Row],[revenue]]-(Sales[[#This Row],[quantity]]*Sales[[#This Row],[unit_cost_ngn]]) -> 22000 | T12: =TEXT(Sales[order_date], "yyyy-mm") -> 2025-02
A13: ORD-7409 | B13: 45706 | C13: Abuja | D13: Ngozi Eze | E13: Walk-in | F13: Sneakers | G13: Fashion | H13: 8 | I13: 27500 | J13: 16500 | K13: 0 | L13: 3 | M13: CUS-2090 | N13: =_xlfn.IFNA(VLOOKUP(Sales[customer_id],Cust[],11,FALSE),"Unknown") -> 50000 | O13: =_xlfn.IFNA(VLOOKUP(Sales[customer_id], Cust[], 7,FALSE),"Unknown customer") -> Abuja | P13: =_xlfn.IFNA(VLOOKUP(Sales[[#This Row],[customer_id]],Cust[],4, FALSE),"Unknown customer") -> Tunde Sanni | Q13: =_xlfn.IFNA(VLOOKUP(Sales[[#This Row],[customer_id]], Cust[], 10, FALSE), "Unknown customer") -> Corporate | R13: =SUM(Sales[quantity]*Sales[[#This Row],[unit_price_ngn]]*(1-Sales[[#This Row],[discount_pct]])) -> 220000 | S13: =Sales[[#This Row],[revenue]]-(Sales[[#This Row],[quantity]]*Sales[[#This Row],[unit_cost_ngn]]) -> 88000 | T13: =TEXT(Sales[order_date], "yyyy-mm") -> 2025-02
A14: ORD-7256 | B14: 45709 | C14: Abuja | D14: Ngozi Eze | E14: Walk-in | F14: Sneakers | G14: Fashion | H14: 4 | I14: 27500 | J14: 16500 | K14: 0.05 | L14: 4 | M14: CUS-2116 | N14: =_xlfn.IFNA(VLOOKUP(Sales[customer_id],Cust[],11,FALSE),"Unknown") -> 500000 | O14: =_xlfn.IFNA(VLOOKUP(Sales[customer_id], Cust[], 7,FALSE),"Unknown customer") -> Abuja | P14: =_xlfn.IFNA(VLOOKUP(Sales[[#This Row],[customer_id]],Cust[],4, FALSE),"Unknown customer") -> Sadiq Chukwu | Q14: =_xlfn.IFNA(VLOOKUP(Sales[[#This Row],[customer_id]], Cust[], 10, FALSE), "Unknown customer") -> Wholesale | R14: =SUM(Sales[quantity]*Sales[[#This Row],[unit_price_ngn]]*(1-Sales[[#This Row],[discount_pct]])) -> 104500 | S14: =Sales[[#This Row],[revenue]]-(Sales[[#This Row],[quantity]]*Sales[[#This Row],[unit_cost_ngn]]) -> 38500 | T14: =TEXT(Sales[order_date], "yyyy-mm") -> 2025-02
... A407: ORD-7415 | B407: 45969 | C407: Lagos | D407: Tunde Bello | E407: Mobile App | F407: Rice 25kg | G407: Groceries | H407: 3 | I407: 46000 | J407: 39000 | K407: 0 | L407: 4 | M407: CUS-9344 | N407: =_xlfn.IFNA(VLOOKUP(Sales[customer_id],Cust[],11,FALSE),"Unknown") -> Unknown | O407: =_xlfn.IFNA(VLOOKUP(Sales[customer_id], Cust[], 7,FALSE),"Unknown customer") -> Unknown customer | P407: =_xlfn.IFNA(VLOOKUP(Sales[[#This Row],[customer_id]],Cust[],4, FALSE),"Unknown customer") -> Unknown customer | Q407: =_xlfn.IFNA(VLOOKUP(Sales[[#This Row],[customer_id]], Cust[], 10, FALSE), "Unknown customer") -> Unknown customer | R407: =SUM(Sales[quantity]*Sales[[#This Row],[unit_price_ngn]]*(1-Sales[[#This Row],[discount_pct]])) -> 138000 | S407: =Sales[[#This Row],[revenue]]-(Sales[[#This Row],[quantity]]*Sales[[#This Row],[unit_cost_ngn]]) -> 21000 | T407: =TEXT(Sales[order_date], "yyyy-mm") -> 2025-11

Sheet Detail1
A1: order_id | B1: order_date | C1: region | D1: sales_rep | E1: channel | F1: product | G1: category | H1: quantity | I1: unit_price_ngn | J1: unit_cost_ngn | K1: discount_pct | L1: delivery_days | M1: customer_id | N1: credit_limit_ngn | O1: city | P1: customer_name | Q1: segment | R1: revenue | S1: Profit_ngn
A2: ORD-7405 | B2: 46022 | C2: Ibadan | D2: Segun Adeyemi | E2: Mobile App | F2: Power Bank 20000mAh | G2: Electronics | H2: 3 | I2: 15500 | J2: 9900 | K2: 0.1 | L2: 2 | M2: CUS-2113 | N2: 100000 | O2: Ibadan | P2: Blessing Nnamdi | Q2: Retail | R2: 41850 | S2: 12150
A3: ORD-7355 | B3: 46018 | C3: Port Harcourt | D3: Chidi Okafor | E3: Web | F3: Ankle Boots | G3: Fashion | H3: 2 | I3: 41000 | J3: 25000 | K3: 0 | L3: 3 | M3: CUS-2020 | N3: 100000 | O3: Port Harcourt | P3: Musa Obi | Q3: Retail | R3: 82000 | S3: 32000
A4: ORD-7233 | B4: 46012 | C4: Lagos | D4: Tunde Bello | E4: Walk-in | F4: Rice 25kg | G4: Groceries | H4: 2 | I4: 46000 | J4: 39000 | K4: 0 | L4: 5 | M4: CUS-2062 | N4: 500000 | O4: Lagos | P4: Nneka Iheanacho | Q4: Retail | R4: 92000 | S4: 14000
A5: ORD-7166 | B5: 45660 | C5: Abuja | D5: Ngozi Eze | E5: Walk-in | F5: Ankle Boots | G5: Fashion | H5: 3 | I5: 41000 | J5: 25000 | K5: 0 | L5: 5 | M5: CUS-2032 | N5: 500000 | O5: Abuja | P5: Amaka Bello | Q5: Retail | R5: 123000 | S5: 48000
A6: ORD-7395 | B6: 45660 | C6: Port Harcourt | D6: Chidi Okafor | E6: Phone | F6: Sneakers | G6: Fashion | H6: 8 | I6: 27500 | J6: 16500 | K6: 0 | L6: 2 | M6: CUS-2038 | N6: 50000 | O6: Port Harcourt | P6: Sadiq Iheanacho | Q6: Retail | R6: 220000 | S6: 88000
A7: ORD-7281 | B7: 46008 | C7: Lagos | D7: Tunde Bello | E7: Web | F7: Body Lotion 400ml | G7: Beauty | H7: 3 | I7: 6800 | J7: 3900 | K7: 0 | L7: 2 | M7: CUS-2036 | N7: 150000 | O7: Lagos | P7: Chiamaka Fashola | Q7: Retail | R7: 20400 | S7: 8700
A8: ORD-7333 | B8: 46005 | C8: Lagos | D8: Amaka Obi | E8: Web | F8: Ankara Fabric 6yd | G8: Textiles | H8: 2 | I8: 12000 | J8: 7200 | K8: 0 | L8: 1 | M8: CUS-2002 | N8: 150000 | O8: Lagos | P8: Lanre Balogun | Q8: Retail | R8: 24000 | S8: 9600
A9: ORD-7387 | B9: 46002 | C9: Port Harcourt | D9: Chidi Okafor | E9: Phone | F9: Rice 25kg | G9: Groceries | H9: 6 | I9: 46000 | J9: 39000 | K9: 0 | L9: 4 | M9: CUS-2019 | N9: 250000 | O9: Port Harcourt | P9: Blessing Sanni | Q9: Retail | R9: 276000 | S9: 42000
A10: ORD-7162 | B10: 45663 | C10: Lagos | D10: Tunde Bello | E10: Walk-in | F10: Rice 25kg | G10: Groceries | H10: 2 | I10: 46000 | J10: 39000 | K10: 0 | L10: 1 | M10: CUS-2111 | N10: 250000 | O10: Lagos | P10: Blessing Obi | Q10: Retail | R10: 92000 | S10: 14000
A11: ORD-7279 | B11: 46002 | C11: Port Harcourt | D11: Chidi Okafor | E11: Phone | F11: Palm Oil 5L | G11: Groceries | H11: 4 | I11: 9800 | J11: 7600 | K11: 0 | L11: 2 | M11: CUS-2019 | N11: 250000 | O11: Port Harcourt | P11: Blessing Sanni | Q11: Retail | R11: 39200 | S11: 8800
A12: ORD-7143 | B12: 45664 | C12: Lagos | D12: Tunde Bello | E12: Walk-in | F12: LED Ring Light | G12: Electronics | H12: 3 | I12: 22000 | J12: 13800 | K12: 0 | L12: 2 | M12: CUS-2077 | N12: 500000 | O12: Lagos | P12: Ibrahim Ogunleye | Q12: Retail | R12: 66000 | S12: 24600
A13: ORD-7126 | B13: 46000 | C13: Lagos | D13: Amaka Obi | E13: Walk-in | F13: Ankle Boots | G13: Fashion | H13: 5 | I13: 41000 | J13: 25000 | K13: 0 | L13: 2 | M13: CUS-2001 | N13: 500000 | O13: Lagos | P13: Halima Adebayo | Q13: Retail | R13: 205000 | S13: 80000
... A204: ORD-7042 | B204: 45838 | C204: Kano | D204: Fatima Yusuf | E204: Mobile App | F204: Ankara Fabric 6yd | G204: Textiles | H204: 4 | I204: 12000 | J204: 7200 | K204: 0 | L204: 7 | M204: CUS-2061 | N204: 250000 | O204: Kano | P204: Funmi Kalu | Q204: Retail | R204: 48000 | S204: 19200

Sheet PVT 1
A1: Row Labels | B1: Sum of revenue | C1: Sum of Profit_ngn | E1: 1
A2: Corporate | B2: 5434670 | C2: 1842370
A3: Retail | B3: 15012155 | C3: 4564955
A4: Unknown customer | B4: 489000 | C4: 152000
A5: Wholesale | B5: 10559100 | C5: 3217000
A6: Grand Total | B6: 31494925 | C6: 9776325

Sheet PVT 2
A1: Sum of revenue | B1: Column Labels | J1: 2
A2: Row Labels | B2: Beauty | C2: Electronics | D2: Fashion | E2: Groceries | F2: Home | G2: Textiles | H2: Grand Total
A3: Abuja | B3: 285600 | C3: 836900 | D3: 1913625 | E3: 2057620 | F3: 422400 | G3: 428000 | H3: 5944145
A4: Ibadan | C4: 1257300 | D4: 723750 | E4: 1023200 | F4: 404800 | G4: 914600 | H4: 4323650
A5: Kano | B5: 13600 | C5: 1174900 | D5: 650150 | E5: 837500 | F5: 832000 | G5: 297200 | H5: 3805350
A6: Lagos | B6: 321980 | C6: 2413875 | D6: 3068250 | E6: 3188240 | F6: 1803200 | G6: 1462000 | H6: 12257545
A7: Port Harcourt | B7: 61200 | C7: 717350 | D7: 1663625 | E7: 1328660 | F7: 579200 | G7: 814200 | H7: 5164235
A8: Grand Total | B8: 682380 | C8: 6400325 | D8: 8019400 | E8: 8435220 | F8: 4041600 | G8: 3916000 | H8: 31494925

Sheet PVT 3
A1: Row Labels | B1: Sum of Profit_ngn | D1: 3
A2: Ankle Boots | B2: 1732150
A3: Sneakers | B3: 1350250
A4: Rice 25kg | B4: 1104300
A5: Wireless Earbuds | B5: 1046325
A6: Lace Material 5yd | B6: 1023700
A7: LED Ring Light | B7: 821300
A8: Blender 1.5L | B8: 755400
A9: Bedsheet Set | B9: 707700
A10: Power Bank 20000mAh | B10: 413800
A11: Ankara Fabric 6yd | B11: 327600
A12: Grand Total | B12: 9282525

Sheet PVT4
A1: Row Labels | B1: Sum of revenue | D1: 4
A2: Jan | B2: 2933595
A3: Feb | B3: 1782810
A4: Mar | B4: 2504700
A5: Apr | B5: 3004950
A6: May | B6: 3064150
A7: Jun | B7: 3193850
A8: Jul | B8: 2117250
A9: Aug | B9: 2738230
A10: Sep | B10: 860650
A11: Oct | B11: 3174045
A12: Nov | B12: 3201295
A13: Dec | B13: 2919400
A14: Grand Total | B14: 31494925

Sheet PVT 5
A1: Row Labels | B1: Sum of revenue | D1: 5
A2: Blessing Ibrahim | B2: 1091100
A3: Amaka Bello | B3: 1033900
A4: Yemi Sanni | B4: 956000
A5: Obinna Oyelaran | B5: 956000
A6: Ibrahim Peters | B6: 703800
A7: Lanre Balogun | B7: 667900
A8: Funmi Musa | B8: 648500
A9: Gbenga Okafor | B9: 631800
A10: Jide Umeh | B10: 603700
A11: Chinelo Lawal | B11: 603500
A12: Grand Total | B12: 7896200

Sheet PVT 6
A1: Row Labels | B1: Count of order_id
A2: Mobile App | B2: 0.28325123
A3: Phone | B3: 0.14285714
A4: Walk-in | B4: 0.25123153
A5: Web | B5: 0.3226601
A6: Grand Total | B6: 1

Sheet 6 PVTs For Dashboard
A1: Row Labels | B1: Sum of revenue | C1: Sum of Profit_ngn
A2: Corporate | B2: 5434670 | C2: 1842370
A3: Retail | B3: 15012155 | C3: 4564955
A4: Unknown customer | B4: 489000 | C4: 152000
A5: Wholesale | B5: 10559100 | C5: 3217000
A6: Grand Total | B6: 31494925 | C6: 9776325
A10: Sum of revenue | B10: Column Labels
A11: Row Labels | B11: Beauty | C11: Electronics | D11: Fashion | E11: Groceries | F11: Home | G11: Textiles | H11: Grand Total
A12: Abuja | B12: 285600 | C12: 836900 | D12: 1913625 | E12: 2057620 | F12: 422400 | G12: 428000 | H12: 5944145
A13: Ibadan | C13: 1257300 | D13: 723750 | E13: 1023200 | F13: 404800 | G13: 914600 | H13: 4323650
A14: Kano | B14: 13600 | C14: 1174900 | D14: 650150 | E14: 837500 | F14: 832000 | G14: 297200 | H14: 3805350
A15: Lagos | B15: 321980 | C15: 2413875 | D15: 3068250 | E15: 3188240 | F15: 1803200 | G15: 1462000 | H15: 12257545
A16: Port Harcourt | B16: 61200 | C16: 717350 | D16: 1663625 | E16: 1328660 | F16: 579200 | G16: 814200 | H16: 5164235
A17: Grand Total | B17: 682380 | C17: 6400325 | D17: 8019400 | E17: 8435220 | F17: 4041600 | G17: 3916000 | H17: 31494925
A21: Row Labels | B21: Sum of Profit_ngn
A22: Ankle Boots | B22: 1732150
A23: Sneakers | B23: 1350250
A24: Rice 25kg | B24: 1104300
A25: Wireless Earbuds | B25: 1046325
A26: Lace Material 5yd | B26: 1023700
A27: LED Ring Light | B27: 821300
A28: Blender 1.5L | B28: 755400
A29: Bedsheet Set | B29: 707700
A30: Power Bank 20000mAh | B30: 413800
A31: Ankara Fabric 6yd | B31: 327600
A32: Grand Total | B32: 9282525
A36: Row Labels | B36: Sum of revenue
A37: Jan | B37: 2933595
A38: Feb | B38: 1782810
A39: Mar | B39: 2504700
A40: Apr | B40: 3004950
A41: May | B41: 3064150
A42: Jun | B42: 3193850
A43: Jul | B43: 2117250
A44: Aug | B44: 2738230
A45: Sep | B45: 860650
A46: Oct | B46: 3174045
A47: Nov | B47: 3201295
A48: Dec | B48: 2919400
A49: Grand Total | B49: 31494925
...

Sheet Summary
A1: Total revenue | B1: =SUM(Sales[revenue]) -> 31494925
A2: Total profit | B2: =SUM(Sales[Profit_ngn]) -> 9776325
A3: Profit margin | B3: =B2/B1 -> 0.31040953
A4: Number of order | B4: =COUNTA(Sales[order_id]) -> 406
A5: Average order value | B5: =AVERAGE(Sales[revenue]) -> 77573.707
A6: Total unit | B6: =SUM(Sales[quantity]) -> 1273
A7: Largest order | B7: =MAX(Sales[revenue]) -> 460000
A8: First order date | B8: =MIN(Sales[order_date]) -> 45659
A9: Last order date | B9: =MAX(Sales[order_date]) -> 46022
A10: Lagos Revenue | B10: =SUMIFS(Sales[revenue], Sales[region], "Lagos") -> 12257545
A11: Lagos share | B11: =B10/B1 -> 0.38919112

Sheet Dashboard
B2: 2025 Sales Performance
B3: FULL 2025 . Data as at 6 January 2026
B5: TOTAL REVENUE | G5: TOTAL PROFIT | L5: AVERAGE ORDER VALUE | Q5: TOTAL UNIT SOLD
B6: =Summary!B1 -> 31494925 | G6: =Summary!B2 -> 9776325 | L6: =Summary!B5 -> 77573.707 | Q6: =Summary!B6 -> 1273
B7: ="across" &Summary!B4&" orders" -> across406 orders | G7: =TEXT(Summary!B3,"0.0%")&"margin" -> 31.0%margin | L7: ="across120customer" -> across120customer | Q7: ="Largestorder"&TEXT(Summary!B7,"#,##0") -> Largestorder460,000

Sheet Targets
A1: Monthly revenue target by region (NGN)
A3: region | B3: monthly_target_ngn
A4: Lagos | B4: 1500000
A5: Abuja | B5: 400000
A6: Port Harcourt | B6: 500000
A7: Kano | B7: 300000
A8: Ibadan | B8: 400000
A11: Other rates used by the business
A12: VAT rate | B12: 0.075
A13: Commission rate | B13: 0.02
A14: Large order threshold (NGN) | B14: 100000
A15: Late delivery threshold (days) | B15: 5
A17: Never type these numbers into a formula. Point at the cell.

Sheet Answers
A1: Formula Ladder — build your answers here
A2: Write the formula in column C. Column D is for what the number means.
A4: # | B4: Business question | C4: Your answer | D4: What it tells the business
A5: RUNG 1 — count and total
A6: 1 | B6: How many orders are in this dataset?
A7: 2 | B7: What is the total quantity sold across the year?
A8: 3 | B8: What is the largest single order quantity?
A9: RUNG 2 — build the missing columns
A10: 4 | B10: Add a revenue column. What is total revenue for the year?
A11: 5 | B11: Add a profit column. What is total profit?
A12: 6 | B12: Add a month column. Which month has the most orders?
A13: RUNG 3 — one condition
A14: 7 | B14: Flag every order over the large-order threshold as “Large”, else “Standard”.
A15: 8 | B15: Flag every delivery over the late threshold as “Late”, else “On time”.
A16: 9 | B16: How many orders were Large AND Late?
A17: RUNG 4 — conditional totals
A18: 10 | B18: What is total revenue for Lagos?
A19: 11 | B19: How many orders came through the Mobile App?
A20: 12 | B20: What is the average order value in Kano?
A21: RUNG 5 — two or more conditions
A22: 13 | B22: Total revenue for Electronics in Lagos.
A23: 14 | B23: Number of Web orders in Q4 (Oct–Dec).
A24: 15 | B24: Average delivery days for Lagos orders placed in December.
A25: RUNG 6 — make it safe and reusable
A26: 16 | B26: Revenue per order for a region, protected against divide-by-zero.
A27: 17 | B27: Did each region beat its monthly target in December? Yes or No.
